<?xml version="1.0" ?>
<!--
  You can echo lidar messages using:
    gz topic -e -t /lidar
-->
<sdf version="1.10">
  <world name="visualize_lidar_world">
    <physics name="1ms" type="ignored">
      <max_step_size>0.001</max_step_size>
      <real_time_factor>1.0</real_time_factor>
    </physics>
    <plugin
      filename="gz-sim-physics-system"
      name="gz::sim::systems::Physics">
    </plugin>
    <plugin
      filename="gz-sim-sensors-system"
      name="gz::sim::systems::Sensors">
      <render_engine>ogre2</render_engine>
    </plugin>
    <plugin
      filename="gz-sim-scene-broadcaster-system"
      name="gz::sim::systems::SceneBroadcaster">
    </plugin>

    <gui fullscreen="0">

      <!-- 3D scene -->
      <plugin filename="MinimalScene" name="3D View">
        <gz-gui>
          <title>3D View</title>
          <property type="bool" key="showTitleBar">false</property>
          <property type="string" key="state">docked</property>
        </gz-gui>

        <engine>ogre2</engine>
        <scene>scene</scene>
        <ambient_light>0.4 0.4 0.4</ambient_light>
        <background_color>0.8 0.8 0.8</background_color>
        <camera_pose>-6 0 6 0 0.5 0</camera_pose>
      </plugin>

      <!-- Plugins that add functionality to the scene -->
      <plugin filename="EntityContextMenuPlugin" name="Entity context menu">
        <gz-gui>
          <property key="state" type="string">floating</property>
          <property key="width" type="double">5</property>
          <property key="height" type="double">5</property>
          <property key="showTitleBar" type="bool">false</property>
        </gz-gui>
      </plugin>
      <plugin filename="GzSceneManager" name="Scene Manager">
        <gz-gui>
          <property key="resizable" type="bool">false</property>
          <property key="width" type="double">5</property>
          <property key="height" type="double">5</property>
          <property key="state" type="string">floating</property>
          <property key="showTitleBar" type="bool">false</property>
        </gz-gui>
      </plugin>
      <plugin filename="InteractiveViewControl" name="Interactive view control">
        <gz-gui>
          <property key="resizable" type="bool">false</property>
          <property key="width" type="double">5</property>
          <property key="height" type="double">5</property>
          <property key="state" type="string">floating</property>
          <property key="showTitleBar" type="bool">false</property>
        </gz-gui>
      </plugin>
      <plugin filename="CameraTracking" name="Camera Tracking">
        <gz-gui>
          <property key="resizable" type="bool">false</property>
          <property key="width" type="double">5</property>
          <property key="height" type="double">5</property>
          <property key="state" type="string">floating</property>
          <property key="showTitleBar" type="bool">false</property>
        </gz-gui>
      </plugin>
      <!-- World control -->
      <plugin filename="WorldControl" name="World control">
        <gz-gui>
          <title>World control</title>
          <property type="bool" key="showTitleBar">false</property>
          <property type="bool" key="resizable">false</property>
          <property type="double" key="height">72</property>
          <property type="double" key="z">1</property>

          <property type="string" key="state">floating</property>
          <anchors target="3D View">
            <line own="left" target="left"/>
            <line own="bottom" target="bottom"/>
          </anchors>
        </gz-gui>

        <play_pause>true</play_pause>
        <step>true</step>
        <start_paused>true</start_paused>
        <use_event>true</use_event>

      </plugin>

      <!-- World statistics -->
      <plugin filename="WorldStats" name="World stats">
        <gz-gui>
          <title>World stats</title>
          <property type="bool" key="showTitleBar">false</property>
          <property type="bool" key="resizable">false</property>
          <property type="double" key="height">110</property>
          <property type="double" key="width">290</property>
          <property type="double" key="z">1</property>

          <property type="string" key="state">floating</property>
          <anchors target="3D View">
            <line own="right" target="right"/>
            <line own="bottom" target="bottom"/>
          </anchors>
        </gz-gui>

        <sim_time>true</sim_time>
        <real_time>true</real_time>
        <real_time_factor>true</real_time_factor>
        <iterations>true</iterations>
      </plugin>

      <plugin filename="VisualizeLidar" name="Visualize Lidar">
      </plugin>

      <!-- Inspector -->
      <plugin filename="ComponentInspector" name="Component inspector">
        <gz-gui>
          <property type="string" key="state">docked</property>
        </gz-gui>
      </plugin>

      <!-- Entity tree -->
      <plugin filename="EntityTree" name="Entity tree">
        <gz-gui>
          <property type="string" key="state">docked</property>
        </gz-gui>
      </plugin>
    </gui>

    <light type="directional" name="sun">
      <cast_shadows>true</cast_shadows>
      <pose>0 0 10 0 0 0</pose>
      <diffuse>0.8 0.8 0.8 1</diffuse>
      <specular>0.2 0.2 0.2 1</specular>
      <attenuation>
        <range>1000</range>
        <constant>0.9</constant>
        <linear>0.01</linear>
        <quadratic>0.001</quadratic>
      </attenuation>
      <direction>-0.5 0.1 -0.9</direction>
    </light>

    <model name="ground_plane">
      <static>true</static>
      <link name="link">
        <collision name="collision">
          <geometry>
            <box>
              <size>20 20 0.1</size>
            </box>
          </geometry>
        </collision>
        <visual name="visual">
          <geometry>
            <box>
              <size>20 20 0.1</size>
            </box>
          </geometry>
          <material>
            <ambient>0.8 0.8 0.8 1</ambient>
            <diffuse>0.8 0.8 0.8 1</diffuse>
            <specular>0.8 0.8 0.8 1</specular>
          </material>
        </visual>
      </link>
    </model>

    <model name="robot_model">
      <static>false</static>
      <pose>1 1 0 0 0 0</pose> <!-- Set initial position and orientation of the robot -->
      <include>
      <material name="silver"><color rgba="0.700 0.700 0.700 1.000"/></material><transmission name="Revolute 3_tran"><type>transmission_interface/SimpleTransmission</type><joint name="Revolute 3"><hardwareInterface>hardware_interface/EffortJointInterface</hardwareInterface></joint><actuator name="Revolute 3_actr"><hardwareInterface>hardware_interface/EffortJointInterface</hardwareInterface><mechanicalReduction>1</mechanicalReduction></actuator></transmission><gazebo><plugin filename="libgazebo_ros_control.so" name="control"/></gazebo><gazebo reference="base_link"><material>Gazebo/Silver</material><mu1>0.2</mu1><mu2>0.2</mu2><self_collide>true</self_collide><gravity>true</gravity></gazebo><gazebo reference="top_1"><material>Gazebo/Silver</material><mu1>0.2</mu1><mu2>0.2</mu2><self_collide>true</self_collide></gazebo><link name="base_link"><inertial><origin rpy="0 0 0" xyz="0.0 0.005 0.0"/><mass value="0.7849999999999999"/><inertia ixx="0.000661" ixy="0.0" ixz="0.0" iyy="0.001308" iyz="0.0" izz="0.000661"/></inertial><visual><origin rpy="0 0 0" xyz="0 0 0"/><geometry><mesh filename="file:///home/scott/GitHub/SAUV-Autonomy/install/sub_description/share/sub_description/meshes/base_link.stl" scale="0.001 0.001 0.001"/></geometry><material name="silver"/></visual><collision><origin rpy="0 0 0" xyz="0 0 0"/><geometry><mesh filename="file:///home/scott/GitHub/SAUV-Autonomy/install/sub_description/share/sub_description/meshes/base_link.stl" scale="0.001 0.001 0.001"/></geometry></collision></link><link name="top_1"><inertial><origin rpy="0 0 0" xyz="0.0 0.004999999999999999 0.0"/><mass value="0.5024"/><inertia ixx="0.000272" ixy="0.0" ixz="0.0" iyy="0.000536" iyz="0.0" izz="0.000272"/></inertial><visual><origin rpy="0 0 0" xyz="-0.0 -0.01 -0.0"/><geometry><mesh filename="file:///home/scott/GitHub/SAUV-Autonomy/install/sub_description/share/sub_description/meshes/top_1.stl" scale="0.001 0.001 0.001"/></geometry><material name="silver"/></visual><collision><origin rpy="0 0 0" xyz="-0.0 -0.01 -0.0"/><geometry><mesh filename="file:///home/scott/GitHub/SAUV-Autonomy/install/sub_description/share/sub_description/meshes/top_1.stl" scale="0.001 0.001 0.001"/></geometry></collision></link><joint name="Revolute 3" type="continuous"><origin rpy="0 0 0" xyz="0.0 0.01 0.0"/><parent link="base_link"/><child link="top_1"/><axis xyz="0.0 1.0 0.0"/></joint></include>
    </model>

  </world>
</sdf>