<?xml version="1.0" ?><!-- =================================================================================== --><!-- |    This document was autogenerated by xacro from /home/scott/GitHub/SAUV-Autonomy/install/sub_description/share/sub_description/urdf/URDF.xacro | --><!-- |    EDITING THIS FILE BY HAND IS NOT RECOMMENDED                                 | --><!-- =================================================================================== --><robot name="URDF"><material name="silver"><color rgba="0.700 0.700 0.700 1.000"/></material><transmission name="Revolute 3_tran"><type>transmission_interface/SimpleTransmission</type><joint name="Revolute 3"><hardwareInterface>hardware_interface/EffortJointInterface</hardwareInterface></joint><actuator name="Revolute 3_actr"><hardwareInterface>hardware_interface/EffortJointInterface</hardwareInterface><mechanicalReduction>1</mechanicalReduction></actuator></transmission><gazebo><plugin filename="libgazebo_ros_control.so" name="control"/></gazebo><gazebo reference="base_link"><material>Gazebo/Silver</material><mu1>0.2</mu1><mu2>0.2</mu2><self_collide>true</self_collide><gravity>true</gravity></gazebo><gazebo reference="top_1"><material>Gazebo/Silver</material><mu1>0.2</mu1><mu2>0.2</mu2><self_collide>true</self_collide></gazebo><link name="base_link"><inertial><origin rpy="0 0 0" xyz="0.0 0.005 0.0"/><mass value="0.7849999999999999"/><inertia ixx="0.000661" ixy="0.0" ixz="0.0" iyy="0.001308" iyz="0.0" izz="0.000661"/></inertial><visual><origin rpy="0 0 0" xyz="0 0 0"/><geometry><mesh filename="file:///home/scott/GitHub/SAUV-Autonomy/install/sub_description/share/sub_description/meshes/base_link.stl" scale="0.001 0.001 0.001"/></geometry><material name="silver"/></visual><collision><origin rpy="0 0 0" xyz="0 0 0"/><geometry><mesh filename="file:///home/scott/GitHub/SAUV-Autonomy/install/sub_description/share/sub_description/meshes/base_link.stl" scale="0.001 0.001 0.001"/></geometry></collision></link><link name="top_1"><inertial><origin rpy="0 0 0" xyz="0.0 0.004999999999999999 0.0"/><mass value="0.5024"/><inertia ixx="0.000272" ixy="0.0" ixz="0.0" iyy="0.000536" iyz="0.0" izz="0.000272"/></inertial><visual><origin rpy="0 0 0" xyz="-0.0 -0.01 -0.0"/><geometry><mesh filename="file:///home/scott/GitHub/SAUV-Autonomy/install/sub_description/share/sub_description/meshes/top_1.stl" scale="0.001 0.001 0.001"/></geometry><material name="silver"/></visual><collision><origin rpy="0 0 0" xyz="-0.0 -0.01 -0.0"/><geometry><mesh filename="file:///home/scott/GitHub/SAUV-Autonomy/install/sub_description/share/sub_description/meshes/top_1.stl" scale="0.001 0.001 0.001"/></geometry></collision></link><joint name="Revolute 3" type="continuous"><origin rpy="0 0 0" xyz="0.0 0.01 0.0"/><parent link="base_link"/><child link="top_1"/><axis xyz="0.0 1.0 0.0"/></joint></robot>
>>> print(robot_urdf)
<?xml version="1.0" ?><!-- =================================================================================== --><!-- |    This document was autogenerated by xacro from /home/scott/GitHub/SAUV-Autonomy/install/sub_description/share/sub_description/urdf/URDF.xacro | --><!-- |    EDITING THIS FILE BY HAND IS NOT RECOMMENDED                                 | --><!-- =================================================================================== --><robot name="URDF"><material name="silver"><color rgba="0.700 0.700 0.700 1.000"/></material><transmission name="Revolute 3_tran"><type>transmission_interface/SimpleTransmission</type><joint name="Revolute 3"><hardwareInterface>hardware_interface/EffortJointInterface</hardwareInterface></joint><actuator name="Revolute 3_actr"><hardwareInterface>hardware_interface/EffortJointInterface</hardwareInterface><mechanicalReduction>1</mechanicalReduction></actuator></transmission><gazebo><plugin filename="libgazebo_ros_control.so" name="control"/></gazebo><gazebo reference="base_link"><material>Gazebo/Silver</material><mu1>0.2</mu1><mu2>0.2</mu2><self_collide>true</self_collide><gravity>true</gravity></gazebo><gazebo reference="top_1"><material>Gazebo/Silver</material><mu1>0.2</mu1><mu2>0.2</mu2><self_collide>true</self_collide></gazebo><link name="base_link"><inertial><origin rpy="0 0 0" xyz="0.0 0.005 0.0"/><mass value="0.7849999999999999"/><inertia ixx="0.000661" ixy="0.0" ixz="0.0" iyy="0.001308" iyz="0.0" izz="0.000661"/></inertial><visual><origin rpy="0 0 0" xyz="0 0 0"/><geometry><mesh filename="file:///home/scott/GitHub/SAUV-Autonomy/install/sub_description/share/sub_description/meshes/base_link.stl" scale="0.001 0.001 0.001"/></geometry><material name="silver"/></visual><collision><origin rpy="0 0 0" xyz="0 0 0"/><geometry><mesh filename="file:///home/scott/GitHub/SAUV-Autonomy/install/sub_description/share/sub_description/meshes/base_link.stl" scale="0.001 0.001 0.001"/></geometry></collision></link><link name="top_1"><inertial><origin rpy="0 0 0" xyz="0.0 0.004999999999999999 0.0"/><mass value="0.5024"/><inertia ixx="0.000272" ixy="0.0" ixz="0.0" iyy="0.000536" iyz="0.0" izz="0.000272"/></inertial><visual><origin rpy="0 0 0" xyz="-0.0 -0.01 -0.0"/><geometry><mesh filename="file:///home/scott/GitHub/SAUV-Autonomy/install/sub_description/share/sub_description/meshes/top_1.stl" scale="0.001 0.001 0.001"/></geometry><material name="silver"/></visual><collision><origin rpy="0 0 0" xyz="-0.0 -0.01 -0.0"/><geometry><mesh filename="file:///home/scott/GitHub/SAUV-Autonomy/install/sub_description/share/sub_description/meshes/top_1.stl" scale="0.001 0.001 0.001"/></geometry></collision></link><joint name="Revolute 3" type="continuous"><origin rpy="0 0 0" xyz="0.0 0.01 0.0"/><parent link="base_link"/><child link="top_1"/><axis xyz="0.0 1.0 0.0"/></joint></robot>