<?xml version="1.0" ?>
<robot name="URDF" xmlns:xacro="http://www.ros.org/wiki/xacro">

<xacro:include filename="$(find sub_description)/urdf/materials.xacro" />
<xacro:include filename="$(find sub_description)/urdf/URDF.trans" />
<xacro:include filename="$(find sub_description)/urdf/URDF.gazebo" />
<link name="base_link">
  <inertial>
    <origin xyz="0.0 0.005 0.0" rpy="0 0 0"/>
    <mass value="0.7849999999999999"/>
    <inertia ixx="0.000661" iyy="0.001308" izz="0.000661" ixy="0.0" iyz="0.0" ixz="0.0"/>
  </inertial>
  <visual>
    <origin xyz="0 0 0" rpy="0 0 0"/>
    <geometry>
      <mesh filename="file://$(find sub_description)/meshes/base_link.stl" scale="0.001 0.001 0.001"/>
    </geometry>
    <material name="silver"/>
  </visual>
  <collision>
    <origin xyz="0 0 0" rpy="0 0 0"/>
    <geometry>
      <mesh filename="file://$(find sub_description)/meshes/base_link.stl" scale="0.001 0.001 0.001"/>
    </geometry>
  </collision>
</link>

<link name="top_1">
  <inertial>
    <origin xyz="0.0 0.004999999999999999 0.0" rpy="0 0 0"/>
    <mass value="0.5024"/>
    <inertia ixx="0.000272" iyy="0.000536" izz="0.000272" ixy="0.0" iyz="0.0" ixz="0.0"/>
  </inertial>
  <visual>
    <origin xyz="-0.0 -0.01 -0.0" rpy="0 0 0"/>
    <geometry>
      <mesh filename="file://$(find sub_description)/meshes/top_1.stl" scale="0.001 0.001 0.001"/>
    </geometry>
    <material name="silver"/>
  </visual>
  <collision>
    <origin xyz="-0.0 -0.01 -0.0" rpy="0 0 0"/>
    <geometry>
      <mesh filename="file://$(find sub_description)/meshes/top_1.stl" scale="0.001 0.001 0.001"/>
    </geometry>
  </collision>
</link>

<joint name="Revolute 3" type="continuous">
  <origin xyz="0.0 0.01 0.0" rpy="0 0 0"/>
  <parent link="base_link"/>
  <child link="top_1"/>
  <axis xyz="0.0 1.0 0.0"/>
</joint>

</robot>
