<?xml version="1.0" ?>
<sdf version="1.6">
	<model name="auv">

        <link name='base_link'>
            <pose>0 0 0 0 0 0</pose>
			<inertial>
				<mass>1000</mass>
				<inertia>
				<ixx>3.000000</ixx>
				<ixy>0.000000</ixy>
				<ixz>0.000000</ixz>
				<iyy>3.000000</iyy>
				<iyz>0.000000</iyz>
				<izz>3.000000</izz>
				</inertia>
			</inertial>
            <visual name='base_visual'>
                <geometry>
                    <box>
                        <size>1 1 1</size>
                    </box>
                </geometry>
            </visual>
            <collision name='base_collision'>
                <geometry>
                    <box>
                        <size>1 1 1</size>
                    </box>
                </geometry>
            </collision>
			<sensor name="imu_sensor" type="imu">
				<always_on>1</always_on>
				<update_rate>1</update_rate>
				<visualize>true</visualize>
				<topic>imu</topic>
			</sensor>
        </link>

        <!-- Thruster Links -->
        <link name='box_1'>
            <pose>0.5 0.5 0.5 0 0 0</pose> <!-- Position adjustment needed -->
            <visual name='thruster_visual_1'>
                <geometry>
                    <box>
                        <size>0.1 0.1 0.1</size>
                    </box>
                </geometry>
            </visual>
            <collision name='thruster_collision_1'>
                <geometry>
                    <box>
                        <size>0.1 0.1 0.1</size>
                    </box>
                </geometry>
            </collision>
        </link>

		<link name='box_2'>
            <pose>0.5 0.5 -0.5 0 0 0</pose> <!-- Position adjustment needed -->
            <visual name='thruster_visual_2'>
                <geometry>
                    <box>
                        <size>0.1 0.1 0.1</size>
                    </box>
                </geometry>
            </visual>
            <collision name='thruster_collision_2'>
                <geometry>
                    <box>
                        <size>0.1 0.1 0.1</size>
                    </box>
                </geometry>
            </collision>
        </link>

		<link name='box_3'>
            <pose>0.5 -0.5 0.5 0 0 0</pose> <!-- Position adjustment needed -->
            <visual name='thruster_visual_3'>
                <geometry>
                    <box>
                        <size>0.1 0.1 0.1</size>
                    </box>
                </geometry>
            </visual>
            <collision name='thruster_collision_3'>
                <geometry>
                    <box>
                        <size>0.1 0.1 0.1</size>
                    </box>
                </geometry>
            </collision>
        </link>

		<link name='box_4'>
            <pose>0.5 -0.5 -0.5 0 0 0</pose> <!-- Position adjustment needed -->
            <visual name='thruster_visual_4'>
                <geometry>
                    <box>
                        <size>0.1 0.1 0.1</size>
                    </box>
                </geometry>
            </visual>
            <collision name='thruster_collision_4'>
                <geometry>
                    <box>
                        <size>0.1 0.1 0.1</size>
                    </box>
                </geometry>
            </collision>
        </link>

		<link name='box_5'>
            <pose>-0.5 0.5 0.5 0 0 0</pose> <!-- Position adjustment needed -->
            <visual name='thruster_visual_5'>
                <geometry>
                    <box>
                        <size>0.1 0.1 0.1</size>
                    </box>
                </geometry>
            </visual>
            <collision name='thruster_collision_5'>
                <geometry>
                    <box>
                        <size>0.1 0.1 0.1</size>
                    </box>
                </geometry>
            </collision>
        </link>

		<link name='box_6'>
            <pose>-0.5 0.5 -0.5 0 0 0</pose> <!-- Position adjustment needed -->
            <visual name='thruster_visual_6'>
                <geometry>
                    <box>
                        <size>0.1 0.1 0.1</size>
                    </box>
                </geometry>
            </visual>
            <collision name='thruster_collision_6'>
                <geometry>
                    <box>
                        <size>0.1 0.1 0.1</size>
                    </box>
                </geometry>
            </collision>
        </link>

		<link name='box_7'>
            <pose>-0.5 -0.5 0.5 0 0 0</pose> <!-- Position adjustment needed -->
            <visual name='thruster_visual_7'>
                <geometry>
                    <box>
                        <size>0.1 0.1 0.1</size>
                    </box>
                </geometry>
            </visual>
            <collision name='thruster_collision_7'>
                <geometry>
                    <box>
                        <size>0.1 0.1 0.1</size>
                    </box>
                </geometry>
            </collision>
        </link>

		<link name='box_8'>
            <pose>-0.5 -0.5 -0.5 0 0 0</pose> <!-- Position adjustment needed -->
            <visual name='thruster_visual_8'>
                <geometry>
                    <box>
                        <size>0.1 0.1 0.1</size>
                    </box>
                </geometry>
            </visual>
            <collision name='thruster_collision_8'>
                <geometry>
                    <box>
                        <size>0.1 0.1 0.1</size>
                    </box>
                </geometry>
            </collision>
        </link>

		<!-- Thruster Joints -->
		<joint name='thruster_1' type='revolute'>
			<pose>0 0 0 0 0 0</pose>
			<parent>base_link</parent>
			<child>box_1</child>
			<axis>
				<xyz>-1 -1 -1</xyz>
				<limit>
					<lower>-1e+12</lower>
					<upper>1e+12</upper>
					<effort>-1</effort>
					<velocity>-1</velocity>
				</limit>
			</axis>
		</joint>

		<joint name='thruster_2' type='revolute'>
			<pose>0 0 0 0 0 0</pose>
			<parent>base_link</parent>
			<child>box_2</child>
			<axis>
				<xyz>-1 -1 1</xyz>
				<limit>
					<lower>-1e+12</lower>
					<upper>1e+12</upper>
					<effort>-1</effort>
					<velocity>-1</velocity>
				</limit>
			</axis>
		</joint>

		<joint name='thruster_3' type='revolute'>
			<pose>0 0 0 0 0 0</pose>
			<parent>base_link</parent>
			<child>box_3</child>
			<axis>
				<xyz>-1 1 -1</xyz>
				<limit>
					<lower>-1e+12</lower>
					<upper>1e+12</upper>
					<effort>-1</effort>
					<velocity>-1</velocity>
				</limit>
			</axis>
		</joint>

		<joint name='thruster_4' type='revolute'>
			<pose>0 0 0 0 0 0</pose>
			<parent>base_link</parent>
			<child>box_4</child>
			<axis>
				<xyz>-1 1 1</xyz>
				<limit>
					<lower>-1e+12</lower>
					<upper>1e+12</upper>
					<effort>-1</effort>
					<velocity>-1</velocity>
				</limit>
			</axis>
		</joint>

		<joint name='thruster_5' type='revolute'>
			<pose>0 0 0 0 0 0</pose>
			<parent>base_link</parent>
			<child>box_5</child>
			<axis>
				<xyz>1 -1 -1</xyz>
				<limit>
					<lower>-1e+12</lower>
					<upper>1e+12</upper>
					<effort>-1</effort>
					<velocity>-1</velocity>
				</limit>
			</axis>
		</joint>

		<joint name='thruster_6' type='revolute'>
			<pose>0 0 0 0 0 0</pose>
			<parent>base_link</parent>
			<child>box_6</child>
			<axis>
				<xyz>1 -1 1</xyz>
				<limit>
					<lower>-1e+12</lower>
					<upper>1e+12</upper>
					<effort>-1</effort>
					<velocity>-1</velocity>
				</limit>
			</axis>
		</joint>

		<joint name='thruster_7' type='revolute'>
			<pose>0 0 0 0 0 0</pose>
			<parent>base_link</parent>
			<child>box_7</child>
			<axis>
				<xyz>1 1 -1</xyz>
				<limit>
					<lower>-1e+12</lower>
					<upper>1e+12</upper>
					<effort>-1</effort>
					<velocity>-1</velocity>
				</limit>
			</axis>
		</joint>

		<joint name='thruster_8' type='revolute'>
			<pose>0 0 0 0 0 0</pose>
			<parent>base_link</parent>
			<child>box_8</child>
			<axis>
				<xyz>1 1 1</xyz>
				<limit>
					<lower>-1e+12</lower>
					<upper>1e+12</upper>
					<effort>-1</effort>
					<velocity>-1</velocity>
				</limit>
			</axis>
		</joint>
	</model>
</sdf>
